Workbook

Sheet 说明与覆盖
A1: Reddit 动物社区 Best 帖子汇总
A2: 抓取时间（UTC）：2026-08-05T11:55:18.816Z ｜ 排序：best ｜ 来源：登录状态下的 Chrome + old.reddit.com 页面
A3: 覆盖说明：帖子清单包含 11 个社区各 300 帖，共 3,300 帖。由于 Chrome 页面抓取必须逐帖打开详情页，本文件仅进一步抓取每个社区最高票帖的可见评论（best 排序、单页最多 500 条）。图片描述以标题作为代理描述，并明确标记为非逐图视觉识别。
A5: 社区 | B5: 帖子数 | C5: 有缩略图 | D5: 帖子票数合计 | E5: 帖子页评论数合计 | F5: 评论详情覆盖帖 | G5: 已抓可见评论 | H5: 未展开占位 | I5: 覆盖帖标题
A6: r/Cats | B6: =COUNTIF(帖子!$A$2:$A$3301,A6) -> 300 | C6: 271 | D6: =SUMIF(帖子!$A$2:$A$3301,A6,帖子!$H$2:$H$3301) -> 276008 | E6: =SUMIF(帖子!$A$2:$A$3301,A6,帖子!$I$2:$I$3301) -> 10959 | F6: 1 | G6: 499 | H6: 73 | I6: Found this kitten at a gas station and trying to decide what’s best for her.
A7: r/aww | B7: =COUNTIF(帖子!$A$2:$A$3301,A7) -> 300 | C7: 299 | D7: =SUMIF(帖子!$A$2:$A$3301,A7,帖子!$H$2:$H$3301) -> 247221 | E7: =SUMIF(帖子!$A$2:$A$3301,A7,帖子!$I$2:$I$3301) -> 4246 | F7: 1 | G7: 149 | H7: 0 | I7: Wife and I adopted these little nuggets yesterday!
A8: r/OneOrangeBraincell | B8: =COUNTIF(帖子!$A$2:$A$3301,A8) -> 300 | C8: 284 | D8: =SUMIF(帖子!$A$2:$A$3301,A8,帖子!$H$2:$H$3301) -> 347737 | E8: =SUMIF(帖子!$A$2:$A$3301,A8,帖子!$I$2:$I$3301) -> 5586 | F8: 1 | G8: 346 | H8: 0 | I8: This is Cheddar. He is very polite
A9: r/AnimalsBeingDerps | B9: =COUNTIF(帖子!$A$2:$A$3301,A9) -> 300 | C9: 296 | D9: =SUMIF(帖子!$A$2:$A$3301,A9,帖子!$H$2:$H$3301) -> 1355692 | E9: =SUMIF(帖子!$A$2:$A$3301,A9,帖子!$I$2:$I$3301) -> 12434 | F9: 1 | G9: 259 | H9: 0 | I9: just couldn't resist it
A10: r/blackcats | B10: =COUNTIF(帖子!$A$2:$A$3301,A10) -> 300 | C10: 288 | D10: =SUMIF(帖子!$A$2:$A$3301,A10,帖子!$H$2:$H$3301) -> 247186 | E10: =SUMIF(帖子!$A$2:$A$3301,A10,帖子!$I$2:$I$3301) -> 5622 | F10: 1 | G10: 271 | H10: 0 | I10: Kiddo went to College.. 😭
A11: r/CatDistributionSystem | B11: =COUNTIF(帖子!$A$2:$A$3301,A11) -> 300 | C11: 293 | D11: =SUMIF(帖子!$A$2:$A$3301,A11,帖子!$H$2:$H$3301) -> 726030 | E11: =SUMIF(帖子!$A$2:$A$3301,A11,帖子!$I$2:$I$3301) -> 16006 | F11: 1 | G11: 482 | H11: 17 | I11: The stray kitten that wandered into my home 2 years ago has grown up and brought home another stray kitten.
A12: r/TuxedoCats | B12: =COUNTIF(帖子!$A$2:$A$3301,A12) -> 300 | C12: 300 | D12: =SUMIF(帖子!$A$2:$A$3301,A12,帖子!$H$2:$H$3301) -> 124890 | E12: =SUMIF(帖子!$A$2:$A$3301,A12,帖子!$I$2:$I$3301) -> 4199 | F12: 1 | G12: 102 | H12: 0 | I12: Siri checking out our new home. She's like a little person! 💕
A13: r/AnimalsBeingBros | B13: =COUNTIF(帖子!$A$2:$A$3301,A13) -> 300 | C13: 258 | D13: =SUMIF(帖子!$A$2:$A$3301,A13,帖子!$H$2:$H$3301) -> 2443236 | E13: =SUMIF(帖子!$A$2:$A$3301,A13,帖子!$I$2:$I$3301) -> 17064 | F13: 1 | G13: 439 | H13: 67 | I13: In Dagestan, a hedgehog approached a passerby so that he could remove the tape from its paw. News we lack
A14: r/Catswithjobs | B14: =COUNTIF(帖子!$A$2:$A$3301,A14) -> 300 | C14: 298 | D14: =SUMIF(帖子!$A$2:$A$3301,A14,帖子!$H$2:$H$3301) -> 335212 | E14: =SUMIF(帖子!$A$2:$A$3301,A14,帖子!$I$2:$I$3301) -> 4090 | F14: 1 | G14: 252 | H14: 0 | I14: Press photograph a dead mouse caught by Larry
A15: r/WhatsWrongWithYourDog | B15: =COUNTIF(帖子!$A$2:$A$3301,A15) -> 300 | C15: 276 | D15: =SUMIF(帖子!$A$2:$A$3301,A15,帖子!$H$2:$H$3301) -> 359189 | E15: =SUMIF(帖子!$A$2:$A$3301,A15,帖子!$I$2:$I$3301) -> 6408 | F15: 1 | G15: 476 | H15: 32 | I15: This is never going to end, is it?
A16: r/rarepuppers | B16: =COUNTIF(帖子!$A$2:$A$3301,A16) -> 300 | C16: 300 | D16: =SUMIF(帖子!$A$2:$A$3301,A16,帖子!$H$2:$H$3301) -> 223549 | E16: =SUMIF(帖子!$A$2:$A$3301,A16,帖子!$I$2:$I$3301) -> 4579 | F16: 1 | G16: 134 | H16: 0 | I16: Just a happy senior boy who’s been enjoying the same patio for 12 years. 🩶
A18: 重要：Reddit 显示的票数和评论数会变化；已删除、折叠、受限或超过页面上限的评论不一定出现在“评论”表。帖子与评论原始链接均保留，便于复核。

Sheet 帖子
A1: 社区 | B1: Best 排名 | C1: 帖子 ID | D1: 帖子标题 | E1: 帖子内容 | F1: 作者 | G1: 发布时间 UTC | H1: 帖子票数 | I1: 帖子评论数 | J1: 评论抓取状态 | K1: 图片内容描述 | L1: 图片描述来源 | M1: Flair | N1: 域名/类型 | O1: 帖子链接 | P1: 媒体链接 | Q1: 缩略图链接 | R1: NSFW | S1: 排序
A2: r/cats | B2: 1 | C2: t3_1uye0qo | D2: Letting users remove posts. | F2: Merari01 | G2: 46219.845 | H2: 52 | I2: 85 | J2: 未打开详情页；仅保留评论总数 | L2: 无可见缩略图 | M2: Discussion | N2: self.cats | O2: https://old.reddit.com/r/cats/comments/1uye0qo/letting_users_remove_posts/ | P2: /r/cats/comments/1uye0qo/letting_users_remove_posts/ | R2: FALSE | S2: best
A3: r/cats | B3: 2 | C3: t3_1vg344w | D3: My best friend 2018 vs 2026. I had just found him on my neighbor's doorstep after a heavy rain | F3: ImplementLogical4130 | G3: 46239.421 | H3: 4246 | I3: 130 | J3: 未打开详情页；仅保留评论总数 | K3: 基于帖子标题推断（非逐图视觉识别）：My best friend 2018 vs 2026. I had just found him on my neighbor's doorstep after a heavy rain | L3: 帖子标题代理描述 | M3: Cat Picture - OC | N3: old.reddit.com | O3: https://old.reddit.com/r/cats/comments/1vg344w/my_best_friend_2018_vs_2026_i_had_just_found_him/ | P3: https://www.reddit.com/gallery/1vg344w | Q3: https://preview.redd.it/jooe9wvz5jhh1.png?width=140&height=105&auto=webp&s=fe176f18782136de8fc4fbc9ed71275c3c8d2ed0 | R3: FALSE | S3: best
A4: r/cats | B4: 3 | C4: t3_1vftd0w | D4: My Boy’s Tail FELL OFF! (TW for pics: pre-op stump and a separated tail) | F4: FilmBuffBrony | G4: 46239.064 | H4: 4837 | I4: 347 | J4: 未打开详情页；仅保留评论总数 | L4: 无可见缩略图 | M4: Cat Picture - OC | N4: old.reddit.com | O4: https://old.reddit.com/r/cats/comments/1vftd0w/my_boys_tail_fell_off_tw_for_pics_preop_stump_and/ | P4: https://www.reddit.com/gallery/1vftd0w | R4: TRUE | S4: best
A5: r/cats | B5: 4 | C5: t3_1vfnmgo | D5: Bart the furious | F5: DarthiusFatticus | G5: 46238.895 | H5: 13449 | I5: 122 | J5: 未打开详情页；仅保留评论总数 | K5: 基于帖子标题推断（非逐图视觉识别）：Bart the furious | L5: 帖子标题代理描述 | M5: Video - Not OC | N5: v.redd.it | O5: https://old.reddit.com/r/cats/comments/1vfnmgo/bart_the_furious/ | P5: https://v.redd.it/4hbbghdvefhh1 | Q5: https://external-preview.redd.it/N2o3cWJrZHZlZmhoMdFy-taTIW5R5LYtdcUNsnD0vk3Elp2WrYQc2NAsRbv_.png?width=140&height=140&crop=1:1,smart&format=jpg&auto=webp&s=f3712a30292dcbe364f03bb79bb8214f86efe1ba | R5: FALSE | S5: best
A6: r/cats | B6: 5 | C6: t3_1vfpxij | D6: Can you believe that I found her in the garbage? | F6: Spare_Equipment3116 | G6: 46238.959 | H6: 6435 | I6: 113 | J6: 未打开详情页；仅保留评论总数 | K6: 基于帖子标题推断（非逐图视觉识别）：Can you believe that I found her in the garbage? | L6: 帖子标题代理描述 | M6: Cat Picture - OC | N6: old.reddit.com | O6: https://old.reddit.com/r/cats/comments/1vfpxij/can_you_believe_that_i_found_her_in_the_garbage/ | P6: https://www.reddit.com/gallery/1vfpxij | Q6: https://preview.redd.it/pnml9izhvfhh1.jpg?width=140&height=140&crop=1:1,smart&auto=webp&s=4f71eb0f288afaa3289002b1831a993105227d5a | R6: FALSE | S6: best
A7: r/cats | B7: 6 | C7: t3_1vfrwvy | D7: The heartthrob, the sensitive one, and the bad boy | F7: RememberTheMaine1996 | G7: 46239.018 | H7: 4680 | I7: 99 | J7: 未打开详情页；仅保留评论总数 | K7: 基于帖子标题推断（非逐图视觉识别）：The heartthrob, the sensitive one, and the bad boy | L7: 帖子标题代理描述 | M7: Cat Picture - OC | N7: i.redd.it | O7: https://old.reddit.com/r/cats/comments/1vfrwvy/the_heartthrob_the_sensitive_one_and_the_bad_boy/ | P7: https://i.redd.it/s8nlf02maghh1.jpeg | Q7: https://preview.redd.it/s8nlf02maghh1.jpeg?width=140&height=140&crop=1:1,smart&auto=webp&s=5a1d5a570d2ee455c7975566cc76d8da711a8cc7 | R7: FALSE | S7: best
A8: r/cats | B8: 7 | C8: t3_1vfwg0r | D8: I bought a little desk toy for myself… my cat decided it belongs to him now | F8: Ok_Site2695 | G8: 46239.164 | H8: 2179 | I8: 35 | J8: 未打开详情页；仅保留评论总数 | K8: 基于帖子标题推断（非逐图视觉识别）：I bought a little desk toy for myself… my cat decided it belongs to him now | L8: 帖子标题代理描述 | M8: Video - OC | N8: v.redd.it | O8: https://old.reddit.com/r/cats/comments/1vfwg0r/i_bought_a_little_desk_toy_for_myself_my_cat/ | P8: https://v.redd.it/7r06cncvbhhh1 | Q8: https://external-preview.redd.it/ZzczcTA5ZHZiaGhoMZzvCKGiBRvgoGZIpAcHmOaenPwf8DJTF_kapeHp2CqB.png?width=140&height=140&crop=1:1,smart&format=jpg&auto=webp&s=e8c466e7287add0df14574d412fe9852d598c96d | R8: FALSE | S8: best
A9: r/cats | B9: 8 | C9: t3_1vg06ga | D9: Decided to adopt the “feral” grandpa (20) | F9: Lost_Ad_6204 | G9: 46239.303 | H9: 1095 | I9: 38 | J9: 未打开详情页；仅保留评论总数 | K9: 基于帖子标题推断（非逐图视觉识别）：Decided to adopt the “feral” grandpa (20) | L9: 帖子标题代理描述 | M9: Adoption | N9: old.reddit.com | O9: https://old.reddit.com/r/cats/comments/1vg06ga/decided_to_adopt_the_feral_grandpa_20/ | P9: https://www.reddit.com/gallery/1vg06ga | Q9: https://preview.redd.it/g9t2fa5nbihh1.jpg?width=140&height=140&crop=1:1,smart&auto=webp&s=b5e56b99d7ae6851a68d7b11bdaff43a3a30999a | R9: FALSE | S9: best
A10: r/cats | B10: 9 | C10: t3_1vfu8k3 | D10: My cat is my entire world, and I don't know what I'd do without him😭♥️ | F10: Significant_Movie814 | G10: 46239.091 | H10: 1858 | I10: 31 | J10: 未打开详情页；仅保留评论总数 | K10: 基于帖子标题推断（非逐图视觉识别）：My cat is my entire world, and I don't know what I'd do without him😭♥️ | L10: 帖子标题代理描述 | M10: Cat Picture - OC | N10: old.reddit.com | O10: https://old.reddit.com/r/cats/comments/1vfu8k3/my_cat_is_my_entire_world_and_i_dont_know_what_id/ | P10: https://www.reddit.com/gallery/1vfu8k3 | Q10: https://preview.redd.it/bb1wd68ftghh1.jpg?width=140&height=140&crop=1:1,smart&auto=webp&s=85f63145f01afff7e60e619cc07a4e7af067fbb5 | R10: FALSE | S10: best
A11: r/cats | B11: 10 | C11: t3_1vfwy88 | D11: He dragged his nuts across my cheese. | F11: lemongelee | G11: 46239.182 | H11: 1201 | I11: 124 | J11: 未打开详情页；仅保留评论总数 | K11: 基于帖子标题推断（非逐图视觉识别）：He dragged his nuts across my cheese. | L11: 帖子标题代理描述 | M11: Humor | N11: i.redd.it | O11: https://old.reddit.com/r/cats/comments/1vfwy88/he_dragged_his_nuts_across_my_cheese/ | P11: https://i.redd.it/kdrfq2yjghhh1.jpeg | Q11: https://preview.redd.it/kdrfq2yjghhh1.jpeg?width=140&height=105&auto=webp&s=adb02237e869fd698b0c0014ff61b04eba35df90 | R11: FALSE | S11: best
A12: r/cats | B12: 11 | C12: t3_1vfyge8 | D12: Cute face, smooth brain | F12: Opening_Bit_8386 | G12: 46239.237 | H12: 888 | I12: 10 | J12: 未打开详情页；仅保留评论总数 | K12: 基于帖子标题推断（非逐图视觉识别）：Cute face, smooth brain | L12: 帖子标题代理描述 | M12: Humor | N12: i.redd.it | O12: https://old.reddit.com/r/cats/comments/1vfyge8/cute_face_smooth_brain/ | P12: https://i.redd.it/h8hj33ndphhh1.png | Q12: https://preview.redd.it/h8hj33ndphhh1.png?width=140&height=140&crop=1:1,smart&auto=webp&s=00355849b6b4dbd5cd7ccdd4d91c4cb3ac88a231 | R12: FALSE | S12: best
A13: r/cats | B13: 12 | C13: t3_1vfih5j | D13: Why does she loaf like this | F13: Realistic-Wheel-7803 | G13: 46238.764 | H13: 8045 | I13: 178 | J13: 未打开详情页；仅保留评论总数 | K13: 基于帖子标题推断（非逐图视觉识别）：Why does she loaf like this | L13: 帖子标题代理描述 | M13: Cat Picture - OC | N13: old.reddit.com | O13: https://old.reddit.com/r/cats/comments/1vfih5j/why_does_she_loaf_like_this/ | P13: https://www.reddit.com/gallery/1vfih5j | Q13: https://preview.redd.it/spz38l4rgehh1.jpg?width=140&height=140&crop=1:1,smart&auto=webp&s=c8dd9e73f0e99778be11972fa00c2bc68e82e643 | R13: FALSE | S13: best
A14: r/cats | B14: 13 | C14: t3_1vfstu4 | D14: After being sick for the past few months, Sundae just had the best 12th birthday | F14: No-Yogurtcloset-1900 | G14: 46239.047 | H14: 1476 | I14: 67 | J14: 未打开详情页；仅保留评论总数 | K14: 基于帖子标题推断（非逐图视觉识别）：After being sick for the past few months, Sundae just had the best 12th birthday | L14: 帖子标题代理描述 | M14: Cat Picture - OC | N14: old.reddit.com | O14: https://old.reddit.com/r/cats/comments/1vfstu4/after_being_sick_for_the_past_few_months_sundae/ | P14: https://www.reddit.com/gallery/1vfstu4 | Q14: https://preview.redd.it/27hdl4iyhghh1.jpg?width=140&height=140&crop=1:1,smart&auto=webp&s=c3b958de6629636d58e1ada2d59b2660e5c0fd0c | R14: FALSE | S14: best
A15: r/cats | B15: 14 | C15: t3_1vfl8kn | D15: When this cat got lost and spotted his human.. | F15: _Eclipse_e | G15: 46238.833 | H15: 3708 | I15: 25 | J15: 未打开详情页；仅保留评论总数 | K15: 基于帖子标题推断（非逐图视觉识别）：When this cat got lost and spotted his human.. | L15: 帖子标题代理描述 | M15: Humor | N15: v.redd.it | O15: https://old.reddit.com/r/cats/comments/1vfl8kn/when_this_cat_got_lost_and_spotted_his_human/ | P15: https://v.redd.it/jb1t9va2zehh1 | Q15: https://external-preview.redd.it/b21yZXlxdzF6ZWhoMd6Pa4eYzmT0UtpQuFAPxs9H1GIkQkyWxpf3xM_UuAoH.png?width=140&height=140&crop=1:1,smart&format=jpg&auto=webp&s=318f9030a0d31a488bbc2b9c154fe80cb1aaace1 | R15: FALSE | S15: best
A16: r/cats | B16: 15 | C16: t3_1vg3xo9 | D16: Do your cats like sitting in boxes? | F16: Beluga_100052 | G16: 46239.451 | H16: 227 | I16: 14 | J16: 未打开详情页；仅保留评论总数 | K16: 基于帖子标题推断（非逐图视觉识别）：Do your cats like sitting in boxes? | L16: 帖子标题代理描述 | M16: Humor | N16: i.redd.it | O16: https://old.reddit.com/r/cats/comments/1vg3xo9/do_your_cats_like_sitting_in_boxes/ | P16: https://i.redd.it/sl67bj8vdjhh1.jpeg | Q16: https://preview.redd.it/sl67bj8vdjhh1.jpeg?width=140&height=140&crop=1:1,smart&auto=webp&s=5641bcb5e4967697f4e2f08c6096984c3673128d | R16: FALSE | S16: best
... A22: r/cats | B22: 21 | C22: t3_1vg1med | D22: Cat became allergic to gabapentin (she’s ok!!!) | F22: specialinterestoftw | G22: 46239.362 | H22: 138 | I22: 6 | J22: 未打开详情页；仅保留评论总数 | K22: 基于帖子标题推断（非逐图视觉识别）：Cat became allergic to gabapentin (she’s ok!!!) | L22: 帖子标题代理描述 | M22: Humor | N22: old.reddit.com | O22: https://old.reddit.com/r/cats/comments/1vg1med/cat_became_allergic_to_gabapentin_shes_ok/ | P22: https://www.reddit.com/gallery/1vg1med | Q22: https://preview.redd.it/a02eg2rtqihh1.jpg?width=140&height=105&auto=webp&s=8ec93ed60f354f111e4b69102065b3255aea5089 | R22: FALSE | S22: best
A23: r/cats | B23: 22 | C23: t3_1vf38ox | D23: Found this kitten at a gas station and trying to decide what’s best for her. | E23: Went to pump gas after clocking off work three days ago and heard a bunch of meows coming from a bush. After walking towards it, a few kitties jumped out and booked it to another bush. This one got left behind and continued to meow like crazy after I picked her up. Took her home and was contemplating on taking her to the local shelter or keeping her. However, I’m still on the fence about it because I’m not really home much and she would probably get lonely if I keep her home alone. Before making any decision though, I at least wanted to give her a name for the time being and was thinking maybe Kate or Negra. Idk im bad with names but suggestions are welcomed and any other advice. TIA | F23: Saudade_Daddy | G23: 46238.306 | H23: 39001 | I23: 1901 | J23: 已抓取该社区最高票帖的可见评论（best，最多500） | K23: 基于帖子标题推断（非逐图视觉识别）：Found this kitten at a gas station and trying to decide what’s best for her. | L23: 帖子标题代理描述 | M23: Advice | N23: i.redd.it | O23: https://old.reddit.com/r/cats/comments/1vf38ox/found_this_kitten_at_a_gas_station_and_trying_to/ | P23: https://i.redd.it/isofcixf7bhh1.jpeg | Q23: https://preview.redd.it/isofcixf7bhh1.jpeg?width=140&height=140&crop=1:1,smart&auto=webp&s=810357016d52dbe20c6eb888500df108854580ed | R23: FALSE | S23: best
A24: r/cats | B24: 23 | C24: t3_1vfzj0s | D24: Bro hears into the future | F24: PixelRealm | G24: 46239.278 | H24: 148 | I24: 13 | J24: 未打开详情页；仅保留评论总数 | K24: 基于帖子标题推断（非逐图视觉识别）：Bro hears into the future | L24: 帖子标题代理描述 | M24: Cat Picture - OC | N24: old.reddit.com | O24: https://old.reddit.com/r/cats/comments/1vfzj0s/bro_hears_into_the_future/ | P24: https://www.reddit.com/gallery/1vfzj0s | Q24: https://preview.redd.it/e67u4x195ihh1.jpg?width=140&height=140&crop=1:1,smart&auto=webp&s=10435e4a8b0decda71d254a0ff530502479ba195 | R24: FALSE | S24: best
A25: r/cats | B25: 24 | C25: t3_1vfk9ve | D25: In Memory of Toucan | F25: Cityfoghorn | G25: 46238.809 | H25: 1107 | I25: 29 | J25: 未打开详情页；仅保留评论总数 | K25: 基于帖子标题推断（非逐图视觉识别）：In Memory of Toucan | L25: 帖子标题代理描述 | M25: Mourning/Loss | N25: old.reddit.com | O25: https://old.reddit.com/r/cats/comments/1vfk9ve/in_memory_of_toucan/ | P25: https://www.reddit.com/gallery/1vfk9ve | Q25: https://preview.redd.it/rxbc9yzwsehh1.jpg?width=140&height=140&crop=1:1,smart&auto=webp&s=8954afe2b5717cfeed78f49c9d69496686fcde4a | R25: FALSE | S25: best
A26: r/cats | B26: 25 | C26: t3_1vfblf5 | D26: The boys like the dollbed | F26: TheCoralie | G26: 46238.594 | H26: 2888 | I26: 43 | J26: 未打开详情页；仅保留评论总数 | K26: 基于帖子标题推断（非逐图视觉识别）：The boys like the dollbed | L26: 帖子标题代理描述 | M26: Cat Picture - OC | N26: i.redd.it | O26: https://old.reddit.com/r/cats/comments/1vfblf5/the_boys_like_the_dollbed/ | P26: https://i.redd.it/cakytgom9dhh1.jpeg | Q26: https://preview.redd.it/cakytgom9dhh1.jpeg?width=140&height=140&crop=1:1,smart&auto=webp&s=a217b42705bb0702f6fae4bb2a161f26e346e488 | R26: FALSE | S26: best
A27: r/cats | B27: 26 | C27: t3_1vfv5bn | D27: Lil cat was brought to my condo. What should I do? | F27: SMOKEYx64 | G27: 46239.121 | H27: 264 | I27: 48 | J27: 未打开详情页；仅保留评论总数 | K27: 基于帖子标题推断（非逐图视觉识别）：Lil cat was brought to my condo. What should I do? | L27: 帖子标题代理描述 | M27: Advice | N27: i.redd.it | O27: https://old.reddit.com/r/cats/comments/1vfv5bn/lil_cat_was_brought_to_my_condo_what_should_i_do/ | P27: https://i.redd.it/d2jyhm0w0hhh1.jpeg | Q27: https://preview.redd.it/d2jyhm0w0hhh1.jpeg?width=140&height=134&auto=webp&s=ce430daf85baae0f2a4c1d8ccc0990b3b1fdc393 | R27: FALSE | S27: best
A28: r/cats | B28: 27 | C28: t3_1vfp1z0 | D28: Why does little baby sleep like this | F28: Fresh_Prize_2505 | G28: 46238.934 | H28: 606 | I28: 73 | J28: 未打开详情页；仅保留评论总数 | K28: 基于帖子标题推断（非逐图视觉识别）：Why does little baby sleep like this | L28: 帖子标题代理描述 | M28: Cat Picture - OC | N28: old.reddit.com | O28: https://old.reddit.com/r/cats/comments/1vfp1z0/why_does_little_baby_sleep_like_this/ | P28: https://www.reddit.com/gallery/1vfp1z0 | Q28: https://preview.redd.it/y1s8h7o0pfhh1.jpg?width=140&height=140&auto=webp&s=28bafbe6c8cf840fa28786c80c5e6783a6c53366 | R28: FALSE | S28: best
A29: r/cats | B29: 28 | C29: t3_1vfpoox | D29: Just adopted: first day with new cat | F29: Economy-Preference75 | G29: 46238.952 | H29: 541 | I29: 43 | J29: 未打开详情页；仅保留评论总数 | K29: 基于帖子标题推断（非逐图视觉识别）：Just adopted: first day with new cat | L29: 帖子标题代理描述 | M29: Adoption | N29: old.reddit.com | O29: https://old.reddit.com/r/cats/comments/1vfpoox/just_adopted_first_day_with_new_cat/ | P29: https://www.reddit.com/gallery/1vfpoox | Q29: https://preview.redd.it/p5ynkqfntfhh1.jpg?width=140&height=140&crop=1:1,smart&auto=webp&s=c3700bc87e3bd2dcb71512ec137ef0e88800f379 | R29: FALSE | S29: best
A30: r/cats | B30: 29 | C30: t3_1vfb880 | D30: 1 eye, 1 brain cell - meet Hange! | F30: Raquilarrr | G30: 46238.585 | H30: 2685 | I30: 50 | J30: 未打开详情页；仅保留评论总数 | K30: 基于帖子标题推断（非逐图视觉识别）：1 eye, 1 brain cell - meet Hange! | L30: 帖子标题代理描述 | M30: Cat Picture - OC | N30: old.reddit.com | O30: https://old.reddit.com/r/cats/comments/1vfb880/1_eye_1_brain_cell_meet_hange/ | P30: https://www.reddit.com/gallery/1vfb880 | Q30: https://preview.redd.it/wvu10ah57dhh1.jpg?width=140&height=140&crop=1:1,smart&auto=webp&s=6596d99a1cf48f3291049c13d717c2c055eab661 | R30: FALSE | S30: best
A31: r/cats | B31: 30 | C31: t3_1vflngu | D31: Had to say goodbye to the sweetest, snuggly boy in the whole world today. His name was Tofu | F31: KDarkOne99 | G31: 46238.843 | H31: 830 | I31: 25 | J31: 未打开详情页；仅保留评论总数 | K31: 基于帖子标题推断（非逐图视觉识别）：Had to say goodbye to the sweetest, snuggly boy in the whole world today. His name was Tofu | L31: 帖子标题代理描述 | M31: Mourning/Loss | N31: i.redd.it | O31: https://old.reddit.com/r/cats/comments/1vflngu/had_to_say_goodbye_to_the_sweetest_snuggly_boy_in/ | P31: https://i.redd.it/mwl91oqp1fhh1.jpeg | Q31: https://preview.redd.it/mwl91oqp1fhh1.jpeg?width=140&height=140&crop=1:1,smart&auto=webp&s=a248c381e0ce32a9673ead346ae91af6cac6c5c2 | R31: FALSE | S31: best
A32: r/cats | B32: 31 | C32: t3_1vg08kv | D32: I am at my wits end. What more can i even do | F32: Hannie0109 | G32: 46239.305 | H32: 104 | I32: 23 | J32: 未打开详情页；仅保留评论总数 | K32: 基于帖子标题推断（非逐图视觉识别）：I am at my wits end. What more can i even do | L32: 帖子标题代理描述 | M32: Medical Questions | N32: i.redd.it | O32: https://old.reddit.com/r/cats/comments/1vg08kv/i_am_at_my_wits_end_what_more_can_i_even_do/ | P32: https://i.redd.it/t67vcvi9cihh1.jpeg | Q32: https://preview.redd.it/t67vcvi9cihh1.jpeg?width=140&height=140&crop=1:1,smart&auto=webp&s=2ca5c1ca020aca8ba601d6ffe4309737f77115f4 | R32: FALSE | S32: best
A33: r/cats | B33: 32 | C33: t3_1vg36u5 | D33: It so hot, that my cat melted lol 😅 | F33: Boring_Apricot454 | G33: 46239.424 | H33: 63 | I33: 7 | J33: 未打开详情页；仅保留评论总数 | K33: 基于帖子标题推断（非逐图视觉识别）：It so hot, that my cat melted lol 😅 | L33: 帖子标题代理描述 | M33: Cat Picture - OC | N33: i.redd.it | O33: https://old.reddit.com/r/cats/comments/1vg36u5/it_so_hot_that_my_cat_melted_lol/ | P33: https://i.redd.it/1763vz6u6jhh1.jpeg | Q33: https://preview.redd.it/1763vz6u6jhh1.jpeg?width=140&height=140&crop=1:1,smart&auto=webp&s=e88f42e3bdff4725f5217f060ca7b6c66717d7ff | R33: FALSE | S33: best
A34: r/cats | B34: 33 | C34: t3_1vg20ud | D34: My lovely little chonky boy Hector is quite unwell🥲 | F34: LittleBoyDavy | G34: 46239.378 | H34: 70 | I34: 12 | J34: 未打开详情页；仅保留评论总数 | K34: 基于帖子标题推断（非逐图视觉识别）：My lovely little chonky boy Hector is quite unwell🥲 | L34: 帖子标题代理描述 | M34: Cat Picture - OC | N34: old.reddit.com | O34: https://old.reddit.com/r/cats/comments/1vg20ud/my_lovely_little_chonky_boy_hector_is_quite_unwell/ | P34: https://www.reddit.com/gallery/1vg20ud | Q34: https://preview.redd.it/xwzw33m1vihh1.jpg?width=140&height=140&crop=1:1,smart&auto=webp&s=1eed385c8bc33d153eb6ab4fff15ec044c7249e9 | R34: FALSE | S34: best
A35: r/cats | B35: 34 | C35: t3_1vg16we | D35: My tiny girl sleeping in my arms💕 | F35: PermissionUpstairs53 | G35: 46239.344 | H35: 74 | I35: 4 | J35: 未打开详情页；仅保留评论总数 | K35: 基于帖子标题推断（非逐图视觉识别）：My tiny girl sleeping in my arms💕 | L35: 帖子标题代理描述 | M35: Cat Picture - OC | N35: old.reddit.com | O35: https://old.reddit.com/r/cats/comments/1vg16we/my_tiny_girl_sleeping_in_my_arms/ | P35: https://www.reddit.com/gallery/1vg16we | Q35: https://preview.redd.it/vdpucj78mihh1.jpg?width=140&height=140&crop=1:1,smart&auto=webp&s=7aa62a85a7cf1ebab5d528aa0e2ed2da50e78a9f | R35: FALSE | S35: best
... A67: r/cats | B67: 66 | C67: t3_1vfbl88 | D67: It's been two weeks since we adopted this rescue cat😺 | F67: nazo_potato_0709 | G67: 46238.594 | H67: 521 | I67: 15 | J67: 未打开详情页；仅保留评论总数 | K67: 基于帖子标题推断（非逐图视觉识别）：It's been two weeks since we adopted this rescue cat😺 | L67: 帖子标题代理描述 | M67: Cat Picture - OC | N67: old.reddit.com | O67: https://old.reddit.com/r/cats/comments/1vfbl88/its_been_two_weeks_since_we_adopted_this_rescue/ | P67: https://www.reddit.com/gallery/1vfbl88 | Q67: https://preview.redd.it/wlvjmt7l9dhh1.jpg?width=140&height=140&crop=1:1,smart&auto=webp&s=fff181c26c09b70c5e589f3e357eabf3300c5812 | R67: FALSE | S67: best
A68: r/cats | B68: 67 | C68: t3_1vg1f8a | D68: I feel guilty about kit-napping my cats but it’s far too late | F68: Easteuroblondie | G68: 46239.353 | H68: 18 | I68: 10 | J68: 未打开详情页；仅保留评论总数 | L68: 无可见缩略图 | M68: Mourning/Loss | N68: self.cats | O68: https://old.reddit.com/r/cats/comments/1vg1f8a/i_feel_guilty_about_kitnapping_my_cats_but_its/ | P68: /r/cats/comments/1vg1f8a/i_feel_guilty_about_kitnapping_my_cats_but_its/ | R68: FALSE | S68: best
A69: r/cats | B69: 68 | C69: t3_1vfqlr8 | D69: Advice for pet grief | F69: PinOld7538 | G69: 46238.979 | H69: 89 | I69: 18 | J69: 未打开详情页；仅保留评论总数 | K69: 基于帖子标题推断（非逐图视觉识别）：Advice for pet grief | L69: 帖子标题代理描述 | M69: Mourning/Loss | N69: i.redd.it | O69: https://old.reddit.com/r/cats/comments/1vfqlr8/advice_for_pet_grief/ | P69: https://i.redd.it/3yudd2vl0ghh1.jpeg | Q69: https://preview.redd.it/3yudd2vl0ghh1.jpeg?width=140&height=140&crop=1:1,smart&auto=webp&s=3c9bb93d667fce28bbd8d273cd28a48f7fc89d10 | R69: FALSE | S69: best
A70: r/cats | B70: 69 | C70: t3_1vg0nll | D70: my little chubby one | F70: lumaria22 | G70: 46239.322 | H70: 20 | I70: 3 | J70: 未打开详情页；仅保留评论总数 | K70: 基于帖子标题推断（非逐图视觉识别）：my little chubby one | L70: 帖子标题代理描述 | M70: Cat Picture - OC | N70: i.redd.it | O70: https://old.reddit.com/r/cats/comments/1vg0nll/my_little_chubby_one/ | P70: https://i.redd.it/b4dmhtdmgihh1.jpeg | Q70: https://preview.redd.it/b4dmhtdmgihh1.jpeg?width=140&height=140&crop=1:1,smart&auto=webp&s=94ddf875eff30c126a4d1ff063abe4f934e1e54b | R70: FALSE | S70: best
A71: r/cats | B71: 70 | C71: t3_1vf2m82 | D71: Cancer Sucks | F71: vvenze | G71: 46238.282 | H71: 1989 | I71: 53 | J71: 未打开详情页；仅保留评论总数 | K71: 基于帖子标题推断（非逐图视觉识别）：Cancer Sucks | L71: 帖子标题代理描述 | M71: Mourning/Loss | N71: old.reddit.com | O71: https://old.reddit.com/r/cats/comments/1vf2m82/cancer_sucks/ | P71: https://www.reddit.com/gallery/1vf2m82 | Q71: https://preview.redd.it/zse9vpac1bhh1.jpg?width=140&height=140&crop=1:1,smart&auto=webp&s=d0c452439f862542507f561a3fcb1a27fc9fef0b | R71: FALSE | S71: best
A72: r/cats | B72: 71 | C72: t3_1vfp7bk | D72: if left empty and unattended this box will contain a cat | F72: ArchtonRDT | G72: 46238.938 | H72: 108 | I72: 9 | J72: 未打开详情页；仅保留评论总数 | K72: 基于帖子标题推断（非逐图视觉识别）：if left empty and unattended this box will contain a cat | L72: 帖子标题代理描述 | M72: Cat Picture - OC | N72: old.reddit.com | O72: https://old.reddit.com/r/cats/comments/1vfp7bk/if_left_empty_and_unattended_this_box_will/ | P72: https://www.reddit.com/gallery/1vfp7bk | Q72: https://preview.redd.it/bc1kiaatpfhh1.jpg?width=140&height=140&crop=1:1,smart&auto=webp&s=9d98fc4ace304ee8065de03fff6f9cd91c22985f | R72: FALSE | S72: best
A73: r/cats | B73: 72 | C73: t3_1vfyewz | D73: She always wants to read | F73: East_Potato_4082 | G73: 46239.235 | H73: 28 | I73: 6 | J73: 未打开详情页；仅保留评论总数 | K73: 基于帖子标题推断（非逐图视觉识别）：She always wants to read | L73: 帖子标题代理描述 | M73: Cat Picture - OC | N73: i.redd.it | O73: https://old.reddit.com/r/cats/comments/1vfyewz/she_always_wants_to_read/ | P73: https://i.redd.it/c0hrgw4duhhh1.jpeg | Q73: https://preview.redd.it/c0hrgw4duhhh1.jpeg?width=140&height=140&crop=1:1,smart&auto=webp&s=75aac3a260ada5a28b7515c4daba5c885eea8875 | R73: FALSE | S73: best
A74: r/cats | B74: 73 | C74: t3_1vfq8wg | D74: Thought I’d show my goofy boy Scooter | F74: Comet_Cosmos15 | G74: 46238.969 | H74: 86 | I74: 11 | J74: 未打开详情页；仅保留评论总数 | K74: 基于帖子标题推断（非逐图视觉识别）：Thought I’d show my goofy boy Scooter | L74: 帖子标题代理描述 | M74: Cat Picture - Not OC | N74: old.reddit.com | O74: https://old.reddit.com/r/cats/comments/1vfq8wg/thought_id_show_my_goofy_boy_scooter/ | P74: https://www.reddit.com/gallery/1vfq8wg | Q74: https://preview.redd.it/m0hc6t3xxfhh1.jpg?width=140&height=140&crop=1:1,smart&auto=webp&s=06222090be267f3599c825259d30104c06a6cbe2 | R74: FALSE | S74: best
A75: r/cats | B75: 74 | C75: t3_1vftmak | D75: Adopted my first cat from a shelter, acclimatizing was going great but he shut down again... | F75: delirifacient | G75: 46239.072 | H75: 54 | I75: 39 | J75: 未打开详情页；仅保留评论总数 | K75: 基于帖子标题推断（非逐图视觉识别）：Adopted my first cat from a shelter, acclimatizing was going great but he shut down again... | L75: 帖子标题代理描述 | M75: Advice | N75: i.redd.it | O75: https://old.reddit.com/r/cats/comments/1vftmak/adopted_my_first_cat_from_a_shelter_acclimatizing/ | P75: https://i.redd.it/8ya0up8ioghh1.jpeg | Q75: https://preview.redd.it/8ya0up8ioghh1.jpeg?width=140&height=140&crop=1:1,smart&auto=webp&s=546f31c4831c51079854c1d873feb0fa224de2b1 | R75: FALSE | S75: best
A76: r/cats | B76: 75 | C76: t3_1vfp6r2 | D76: Hi im Meimei | F76: tinovps | G76: 46238.938 | H76: 91 | I76: 5 | J76: 未打开详情页；仅保留评论总数 | K76: 基于帖子标题推断（非逐图视觉识别）：Hi im Meimei | L76: 帖子标题代理描述 | M76: Cat Picture - OC | N76: old.reddit.com | O76: https://old.reddit.com/r/cats/comments/1vfp6r2/hi_im_meimei/ | P76: https://www.reddit.com/gallery/1vfp6r2 | Q76: https://preview.redd.it/ocm8o98zpfhh1.jpg?width=140&height=140&crop=1:1,smart&auto=webp&s=97464f13509ce4783d86cbfa2abc810e69cbbf3c | R76: FALSE | S76: best
...

Sheet 评论
A1: 社区 | B1: 帖子 ID | C1: 帖子标题 | D1: 评论 ID | E1: 层级 | F1: 评论作者 | G1: 评论时间 UTC | H1: 评论票数 | I1: 评论内容 | J1: 评论链接 | K1: 帖子链接
A2: r/cats | B2: t3_1vf38ox | C2: Found this kitten at a gas station and trying to decide what’s best for her. | D2: t1_p1ltgvu | E2: 0 | F2: rdeluna | G2: 46238.31 | H2: 5986 | I2: Hmm not sure which fruits are best but I can tell that chair / home sure looks best for her. OP, looks like you’ve been chosen, if it’s possible, you’d both make a happy family. | J2: https://old.reddit.com/r/cats/comments/1vf38ox/found_this_kitten_at_a_gas_station_and_trying_to/p1ltgvu/ | K2: https://old.reddit.com/r/cats/comments/1vf38ox/found_this_kitten_at_a_gas_station_and_trying_to/
A3: r/cats | B3: t3_1vf38ox | C3: Found this kitten at a gas station and trying to decide what’s best for her. | D3: t1_p1ltf6e | E3: 0 | F3: Confident_Lecture498 | G3: 46238.31 | H3: 4221 | I3: Dang what a perfect photo | J3: https://old.reddit.com/r/cats/comments/1vf38ox/found_this_kitten_at_a_gas_station_and_trying_to/p1ltf6e/ | K3: https://old.reddit.com/r/cats/comments/1vf38ox/found_this_kitten_at_a_gas_station_and_trying_to/
A4: r/cats | B4: t3_1vf38ox | C4: Found this kitten at a gas station and trying to decide what’s best for her. | D4: t1_p1ltqn8 | E4: 0 | F4: Important_Wrap772 | G4: 46238.312 | H4: 3870 | I4: Get a second cat so they can keep each other company | J4: https://old.reddit.com/r/cats/comments/1vf38ox/found_this_kitten_at_a_gas_station_and_trying_to/p1ltqn8/ | K4: https://old.reddit.com/r/cats/comments/1vf38ox/found_this_kitten_at_a_gas_station_and_trying_to/
A5: r/cats | B5: t3_1vf38ox | C5: Found this kitten at a gas station and trying to decide what’s best for her. | D5: t1_p1lw2aw | E5: 0 | F5: Semjaja | G5: 46238.325 | H5: 2605 | I5: Not sure if I should keep her but in the meantime, let me name her and get her a collar You're not fooling anyone OP (well maybe yourself). I think she's staying... | J5: https://old.reddit.com/r/cats/comments/1vf38ox/found_this_kitten_at_a_gas_station_and_trying_to/p1lw2aw/ | K5: https://old.reddit.com/r/cats/comments/1vf38ox/found_this_kitten_at_a_gas_station_and_trying_to/
A6: r/cats | B6: t3_1vf38ox | C6: Found this kitten at a gas station and trying to decide what’s best for her. | D6: t1_p1m2dew | E6: 0 | F6: Calm_Possibility9024 | G6: 46238.362 | H6: 1858 | I6: I love how she's got her front paws on the table like she's a little human | J6: https://old.reddit.com/r/cats/comments/1vf38ox/found_this_kitten_at_a_gas_station_and_trying_to/p1m2dew/ | K6: https://old.reddit.com/r/cats/comments/1vf38ox/found_this_kitten_at_a_gas_station_and_trying_to/
A7: r/cats | B7: t3_1vf38ox | C7: Found this kitten at a gas station and trying to decide what’s best for her. | D7: t1_p1lu5in | E7: 0 | F7: twinno2 | G7: 46238.314 | H7: 1462 | I7: If you go back and snag another kitty, they will entertain each other if you keep two. | J7: https://old.reddit.com/r/cats/comments/1vf38ox/found_this_kitten_at_a_gas_station_and_trying_to/p1lu5in/ | K7: https://old.reddit.com/r/cats/comments/1vf38ox/found_this_kitten_at_a_gas_station_and_trying_to/
A8: r/cats | B8: t3_1vf38ox | C8: Found this kitten at a gas station and trying to decide what’s best for her. | D8: t1_p1lvva1 | E8: 0 | F8: Freyjia1 | G8: 46238.324 | H8: 812 | I8: Ive seen cats go nuts for watermelon and strawberries, dunno about the other 3 | J8: https://old.reddit.com/r/cats/comments/1vf38ox/found_this_kitten_at_a_gas_station_and_trying_to/p1lvva1/ | K8: https://old.reddit.com/r/cats/comments/1vf38ox/found_this_kitten_at_a_gas_station_and_trying_to/
A9: r/cats | B9: t3_1vf38ox | C9: Found this kitten at a gas station and trying to decide what’s best for her. | D9: t1_p1lx0to | E9: 0 | F9: BranFendigaidd | G9: 46238.331 | H9: 808 | I9: to not be alone, go back to the gas station, find the other kittens. Take them. Leave 2 for you and the rest find a home or a non-kill shelter (kittens are adopted extremely fast) | J9: https://old.reddit.com/r/cats/comments/1vf38ox/found_this_kitten_at_a_gas_station_and_trying_to/p1lx0to/ | K9: https://old.reddit.com/r/cats/comments/1vf38ox/found_this_kitten_at_a_gas_station_and_trying_to/
A10: r/cats | B10: t3_1vf38ox | C10: Found this kitten at a gas station and trying to decide what’s best for her. | D10: t1_p1nc28d | E10: 0 | F10: dc469 | G10: 46238.565 | H10: 685 | I10: I came to say exactly this. OP got her a collar. That was unnecessary money spent (unlike kibble or litter). They just need us to have someone tell them they made the right decision. 🥰 | J10: https://old.reddit.com/r/cats/comments/1vf38ox/found_this_kitten_at_a_gas_station_and_trying_to/p1nc28d/ | K10: https://old.reddit.com/r/cats/comments/1vf38ox/found_this_kitten_at_a_gas_station_and_trying_to/
A11: r/cats | B11: t3_1vf38ox | C11: Found this kitten at a gas station and trying to decide what’s best for her. | D11: t1_p1m5y02 | E11: 0 | F11: Valkyriesride1 | G11: 46238.382 | H11: 660 | I11: My cat loves watermelon, but she doesn't like cantaloupe. Op, if you are concerned about her being lonely, ask the cat distribution system to give you another baby from litter and go back to bush you found her at with a couple of cans of cat food. Thank you for rescuing her. If you decide not to keep her, please find a rescue or no kill shelter. Please don't give her away to anyone you don't know personally, there are a lot of people out there search for free animals to use or bait animals or will do other horrific things to them. | J11: https://old.reddit.com/r/cats/comments/1vf38ox/found_this_kitten_at_a_gas_station_and_trying_to/p1m5y02/ | K11: https://old.reddit.com/r/cats/comments/1vf38ox/found_this_kitten_at_a_gas_station_and_trying_to/
A12: r/cats | B12: t3_1vf38ox | C12: Found this kitten at a gas station and trying to decide what’s best for her. | D12: t1_p1n324i | E12: 0 | F12: Livid_Walrus7829 | G12: 46238.535 | H12: 620 | I12: Stop cause this looks exactly my baby when she was found at a gas station. Even the same collar. Shes a year now. <image> | J12: https://old.reddit.com/r/cats/comments/1vf38ox/found_this_kitten_at_a_gas_station_and_trying_to/p1n324i/ | K12: https://old.reddit.com/r/cats/comments/1vf38ox/found_this_kitten_at_a_gas_station_and_trying_to/
A13: r/cats | B13: t3_1vf38ox | C13: Found this kitten at a gas station and trying to decide what’s best for her. | D13: t1_p1lvfrq | E13: 0 | F13: Foreveralone84 | G13: 46238.322 | H13: 586 | I13: The only sensible suggestion... Up you go! | J13: https://old.reddit.com/r/cats/comments/1vf38ox/found_this_kitten_at_a_gas_station_and_trying_to/p1lvfrq/ | K13: https://old.reddit.com/r/cats/comments/1vf38ox/found_this_kitten_at_a_gas_station_and_trying_to/
... A29: r/cats | B29: t3_1vf38ox | C29: Found this kitten at a gas station and trying to decide what’s best for her. | D29: t1_p1mivnx | E29: 0 | F29: FunArtichoke8706 | G29: 46238.452 | H29: 195 | I29: But if you get more, try not to leave just one alone outside :( | J29: https://old.reddit.com/r/cats/comments/1vf38ox/found_this_kitten_at_a_gas_station_and_trying_to/p1mivnx/ | K29: https://old.reddit.com/r/cats/comments/1vf38ox/found_this_kitten_at_a_gas_station_and_trying_to/
A30: r/cats | B30: t3_1vf38ox | C30: Found this kitten at a gas station and trying to decide what’s best for her. | D30: t1_p1px7az | E30: 0 | F30: strong_systems | G30: 46238.842 | H30: 176 | J30: https://old.reddit.com/r/cats/comments/1vf38ox/found_this_kitten_at_a_gas_station_and_trying_to/p1px7az/ | K30: https://old.reddit.com/r/cats/comments/1vf38ox/found_this_kitten_at_a_gas_station_and_trying_to/
A31: r/cats | B31: t3_1vf38ox | C31: Found this kitten at a gas station and trying to decide what’s best for her. | D31: t1_p1qk29w | E31: 0 | F31: i_AM_A-ShArk | G31: 46238.914 | H31: 176 | I31: You put a collar on her, you’re not debating anything | J31: https://old.reddit.com/r/cats/comments/1vf38ox/found_this_kitten_at_a_gas_station_and_trying_to/p1qk29w/ | K31: https://old.reddit.com/r/cats/comments/1vf38ox/found_this_kitten_at_a_gas_station_and_trying_to/
A32: r/cats | B32: t3_1vf38ox | C32: Found this kitten at a gas station and trying to decide what’s best for her. | D32: t1_p1nt023 | E32: 0 | F32: madampc | G32: 46238.619 | H32: 175 | I32: The cat distribution system gave me this one, which also looks like yours <image> | J32: https://old.reddit.com/r/cats/comments/1vf38ox/found_this_kitten_at_a_gas_station_and_trying_to/p1nt023/ | K32: https://old.reddit.com/r/cats/comments/1vf38ox/found_this_kitten_at_a_gas_station_and_trying_to/
A33: r/cats | B33: t3_1vf38ox | C33: Found this kitten at a gas station and trying to decide what’s best for her. | D33: t1_p1mkr5t | E33: 0 | F33: early_birdy | G33: 46238.46 | H33: 143 | I33: You mean the cat dispensing system? | J33: https://old.reddit.com/r/cats/comments/1vf38ox/found_this_kitten_at_a_gas_station_and_trying_to/p1mkr5t/ | K33: https://old.reddit.com/r/cats/comments/1vf38ox/found_this_kitten_at_a_gas_station_and_trying_to/
A34: r/cats | B34: t3_1vf38ox | C34: Found this kitten at a gas station and trying to decide what’s best for her. | D34: t1_p1n792q | E34: 0 | F34: pandasareliars | G34: 46238.549 | H34: 137 | I34: Kittens are easier to raise in sets? I see what you're trying to do here and I like it. | J34: https://old.reddit.com/r/cats/comments/1vf38ox/found_this_kitten_at_a_gas_station_and_trying_to/p1n792q/ | K34: https://old.reddit.com/r/cats/comments/1vf38ox/found_this_kitten_at_a_gas_station_and_trying_to/
A35: r/cats | B35: t3_1vf38ox | C35: Found this kitten at a gas station and trying to decide what’s best for her. | D35: t1_p1m18ze | E35: 0 | F35: Cloaked42m | G35: 46238.355 | H35: 134 | I35: They always may prefer wet food but dry kibble is fine. Measure the dry food. If it says a half cup per day, split it between breakfast and dinner. If you share your dinner, teach her manners or she'll yank your sandwich out of your hand. Cats understand No at an early age. Just say No firmly and give her a firm tap on her forehead if she goes for your food. Priorities are shots and spayed. And yes, they are happiest with another cat. | J35: https://old.reddit.com/r/cats/comments/1vf38ox/found_this_kitten_at_a_gas_station_and_trying_to/p1m18ze/ | K35: https://old.reddit.com/r/cats/comments/1vf38ox/found_this_kitten_at_a_gas_station_and_trying_to/
A36: r/cats | B36: t3_1vf38ox | C36: Found this kitten at a gas station and trying to decide what’s best for her. | D36: t1_p1ncmcr | E36: 0 | F36: Semjaja | G36: 46238.567 | H36: 129 | I36: Definitely the right decision! | J36: https://old.reddit.com/r/cats/comments/1vf38ox/found_this_kitten_at_a_gas_station_and_trying_to/p1ncmcr/ | K36: https://old.reddit.com/r/cats/comments/1vf38ox/found_this_kitten_at_a_gas_station_and_trying_to/
A37: r/cats | B37: t3_1vf38ox | C37: Found this kitten at a gas station and trying to decide what’s best for her. | D37: t1_p1rijns | E37: 0 | F37: Ok-Scheme8634 | G37: 46239.037 | H37: 121 | I37: My boy when he was a kitten. The couch was a futon without arm rests so it reminded me of a therapist couch a little, and he reminds me of a teeny therapist waiting for you to get on the couch so he can listen while making biscuits in your intestines lol <image> | J37: https://old.reddit.com/r/cats/comments/1vf38ox/found_this_kitten_at_a_gas_station_and_trying_to/p1rijns/ | K37: https://old.reddit.com/r/cats/comments/1vf38ox/found_this_kitten_at_a_gas_station_and_trying_to/
A38: r/cats | B38: t3_1vf38ox | C38: Found this kitten at a gas station and trying to decide what’s best for her. | D38: t1_p1otr2x | E38: 0 | F38: Steadyandquick | G38: 46238.726 | H38: 117 | I38: Yes! She was in a bush in a gas station! You saved her from getting hit by a car or worse. You could always return to said bush and bring home a sibling! They would tire each other out and be grateful. You are a great human! | J38: https://old.reddit.com/r/cats/comments/1vf38ox/found_this_kitten_at_a_gas_station_and_trying_to/p1otr2x/ | K38: https://old.reddit.com/r/cats/comments/1vf38ox/found_this_kitten_at_a_gas_station_and_trying_to/
A39: r/cats | B39: t3_1vf38ox | C39: Found this kitten at a gas station and trying to decide what’s best for her. | D39: t1_p1m2ktz | E39: 0 | F39: Zherneb | G39: 46238.363 | H39: 116 | I39: Then a third cat so when they fight, they have someone else to cuddle with. Then a forth so there is no cat ever alone when any argue! Then a fifth because it's cute and fluffy! | J39: https://old.reddit.com/r/cats/comments/1vf38ox/found_this_kitten_at_a_gas_station_and_trying_to/p1m2ktz/ | K39: https://old.reddit.com/r/cats/comments/1vf38ox/found_this_kitten_at_a_gas_station_and_trying_to/
A40: r/cats | B40: t3_1vf38ox | C40: Found this kitten at a gas station and trying to decide what’s best for her. | D40: t1_p1niz7s | E40: 0 | F40: Oykatet | G40: 46238.588 | H40: 107 | I40: I hope they see this comment because that would just be heartbreaking. They should grab them all and keep 2 and find homes for the others. How can they be absolutely sure they aren't leaving one behind though? | J40: https://old.reddit.com/r/cats/comments/1vf38ox/found_this_kitten_at_a_gas_station_and_trying_to/p1niz7s/ | K40: https://old.reddit.com/r/cats/comments/1vf38ox/found_this_kitten_at_a_gas_station_and_trying_to/
A41: r/cats | B41: t3_1vf38ox | C41: Found this kitten at a gas station and trying to decide what’s best for her. | D41: t1_p1nc8cp | E41: 0 | F41: Sveitsinvaltaaja | G41: 46238.566 | H41: 94 | I41: My cat loved honeydew <image> | J41: https://old.reddit.com/r/cats/comments/1vf38ox/found_this_kitten_at_a_gas_station_and_trying_to/p1nc8cp/ | K41: https://old.reddit.com/r/cats/comments/1vf38ox/found_this_kitten_at_a_gas_station_and_trying_to/
A42: r/cats | B42: t3_1vf38ox | C42: Found this kitten at a gas station and trying to decide what’s best for her. | D42: t1_p1mithp | E42: 0 | F42: Crazy_Opposite_4264 | G42: 46238.451 | H42: 94 | I42: She already looks like she belongs there and it's honestly hard not to smile at that. | J42: https://old.reddit.com/r/cats/comments/1vf38ox/found_this_kitten_at_a_gas_station_and_trying_to/p1mithp/ | K42: https://old.reddit.com/r/cats/comments/1vf38ox/found_this_kitten_at_a_gas_station_and_trying_to/
... A45: r/cats | B45: t3_1vf38ox | C45: Found this kitten at a gas station and trying to decide what’s best for her. | D45: t1_p1p1blf | E45: 0 | F45: Shattingpancreas_ | G45: 46238.748 | H45: 86 | I45: <image> I also found a cat last week. The vet thinks she’s about four months old. | J45: https://old.reddit.com/r/cats/comments/1vf38ox/found_this_kitten_at_a_gas_station_and_trying_to/p1p1blf/ | K45: https://old.reddit.com/r/cats/comments/1vf38ox/found_this_kitten_at_a_gas_station_and_trying_to/
A46: r/cats | B46: t3_1vf38ox | C46: Found this kitten at a gas station and trying to decide what’s best for her. | D46: t1_p1ov1sz | E46: 0 | F46: FunkyInclination | G46: 46238.73 | H46: 85 | J46: https://old.reddit.com/r/cats/comments/1vf38ox/found_this_kitten_at_a_gas_station_and_trying_to/p1ov1sz/ | K46: https://old.reddit.com/r/cats/comments/1vf38ox/found_this_kitten_at_a_gas_station_and_trying_to/
A47: r/cats | B47: t3_1vf38ox | C47: Found this kitten at a gas station and trying to decide what’s best for her. | D47: t1_p1n0w8v | E47: 0 | F47: WenDeckerstArt | G47: 46238.527 | H47: 85 | I47: You put a collar on her? She’s yours now!! Congratulations!!! | J47: https://old.reddit.com/r/cats/comments/1vf38ox/found_this_kitten_at_a_gas_station_and_trying_to/p1n0w8v/ | K47: https://old.reddit.com/r/cats/comments/1vf38ox/found_this_kitten_at_a_gas_station_and_trying_to/
A48: r/cats | B48: t3_1vf38ox | C48: Found this kitten at a gas station and trying to decide what’s best for her. | D48: t1_p1ms6u2 | E48: 0 | F48: dancingpianofairy | G48: 46238.493 | H48: 83 | I48: OP mentioned the others skedaddled. The only reason they got this one was because she stayed. | J48: https://old.reddit.com/r/cats/comments/1vf38ox/found_this_kitten_at_a_gas_station_and_trying_to/p1ms6u2/ | K48: https://old.reddit.com/r/cats/comments/1vf38ox/found_this_kitten_at_a_gas_station_and_trying_to/
A49: r/cats | B49: t3_1vf38ox | C49: Found this kitten at a gas station and trying to decide what’s best for her. | D49: t1_p1n5tcz | E49: 0 | F49: Queasy-Celery-7982 | G49: 46238.544 | H49: 81 | I49: All of my animals I get in pairs for this reason. :) | J49: https://old.reddit.com/r/cats/comments/1vf38ox/found_this_kitten_at_a_gas_station_and_trying_to/p1n5tcz/ | K49: https://old.reddit.com/r/cats/comments/1vf38ox/found_this_kitten_at_a_gas_station_and_trying_to/
A50: r/cats | B50: t3_1vf38ox | C50: Found this kitten at a gas station and trying to decide what’s best for her. | D50: t1_p1ndsip | E50: 0 | F50: Serious-Tiger734 | G50: 46238.571 | H50: 74 | I50: I prefer in triplets. This helps when one cat is moody and wants to be left alone. This lets the other two cuddle. On those days when everyone is happy they can form a puddle. It always seems one of them is moody on any given day | J50: https://old.reddit.com/r/cats/comments/1vf38ox/found_this_kitten_at_a_gas_station_and_trying_to/p1ndsip/ | K50: https://old.reddit.com/r/cats/comments/1vf38ox/found_this_kitten_at_a_gas_station_and_trying_to/
A51: r/cats | B51: t3_1vf38ox | C51: Found this kitten at a gas station and trying to decide what’s best for her. | D51: t1_p1lukmh | E51: 0 | F51: KeeKyieTheMorris | G51: 46238.316 | H51: 70 | I51: 😍 oh my gah She is such a cutie pie. Is it possible to try to find the other kitties? I’m not an expert but every cat is different so it’s hard to know if she’ll be lonely or not later on when she’s older | J51: https://old.reddit.com/r/cats/comments/1vf38ox/found_this_kitten_at_a_gas_station_and_trying_to/p1lukmh/ | K51: https://old.reddit.com/r/cats/comments/1vf38ox/found_this_kitten_at_a_gas_station_and_trying_to/
A52: r/cats | B52: t3_1vf38ox | C52: Found this kitten at a gas station and trying to decide what’s best for her. | D52: t1_p1mmcbd | E52: 0 | F52: ericlikesyou | G52: 46238.468 | H52: 68 | I52: im glad someone else is saying this, not really a CDS situation imo | J52: https://old.reddit.com/r/cats/comments/1vf38ox/found_this_kitten_at_a_gas_station_and_trying_to/p1mmcbd/ | K52: https://old.reddit.com/r/cats/comments/1vf38ox/found_this_kitten_at_a_gas_station_and_trying_to/
A53: r/cats | B53: t3_1vf38ox | C53: Found this kitten at a gas station and trying to decide what’s best for her. | D53: t1_p1n062c | E53: 0 | F53: LevelPerception4 | G53: 46238.524 | H53: 67 | I53: Much, much easier! They will entertain and be company for each other while you’re at work. | J53: https://old.reddit.com/r/cats/comments/1vf38ox/found_this_kitten_at_a_gas_station_and_trying_to/p1n062c/ | K53: https://old.reddit.com/r/cats/comments/1vf38ox/found_this_kitten_at_a_gas_station_and_trying_to/
A54: r/cats | B54: t3_1vf38ox | C54: Found this kitten at a gas station and trying to decide what’s best for her. | D54: t1_p1s14oh | E54: 0 | F54: abroberts1 | G54: 46239.108 | H54: 65 | I54: That looks like a stock photo 😂 | J54: https://old.reddit.com/r/cats/comments/1vf38ox/found_this_kitten_at_a_gas_station_and_trying_to/p1s14oh/ | K54: https://old.reddit.com/r/cats/comments/1vf38ox/found_this_kitten_at_a_gas_station_and_trying_to/
A55: r/cats | B55: t3_1vf38ox | C55: Found this kitten at a gas station and trying to decide what’s best for her. | D55: t1_p1lx1q2 | E55: 0 | F55: Saudade_Daddy | G55: 46238.331 | H55: 65 | I55: I did happen to stop by earlier today before I got home but I didn’t hear or see them. I think they set up their home behind the gas station where they keep the dumpsters in a fenced area, which is locked. Not 100% sure but if I was a momma cat with babies I’d set up shop right there. | J55: https://old.reddit.com/r/cats/comments/1vf38ox/found_this_kitten_at_a_gas_station_and_trying_to/p1lx1q2/ | K55: https://old.reddit.com/r/cats/comments/1vf38ox/found_this_kitten_at_a_gas_station_and_trying_to/
A56: r/cats | B56: t3_1vf38ox | C56: Found this kitten at a gas station and trying to decide what’s best for her. | D56: t1_p1otj0g | E56: 0 | F56: Queasy-Celery-7982 | G56: 46238.726 | H56: 62 | I56: PS, I have two cats, two dogs, two guinea pigs, two fish. I only strayed from this rule with 3 daughters and one husband. :) | J56: https://old.reddit.com/r/cats/comments/1vf38ox/found_this_kitten_at_a_gas_station_and_trying_to/p1otj0g/ | K56: https://old.reddit.com/r/cats/comments/1vf38ox/found_this_kitten_at_a_gas_station_and_trying_to/
A57: r/cats | B57: t3_1vf38ox | C57: Found this kitten at a gas station and trying to decide what’s best for her. | D57: t1_p1nyipv | E57: 0 | F57: ggt3416 | G57: 46238.635 | H57: 62 | I57: Honestly OP, this is sound advice. Kittens are amazing in pairs. If you can go back and grab one of the other gas station bush baby, that would be best. They will keep each other company and I promise taking care of 2 is easier than it seems. | J57: https://old.reddit.com/r/cats/comments/1vf38ox/found_this_kitten_at_a_gas_station_and_trying_to/p1nyipv/ | K57: https://old.reddit.com/r/cats/comments/1vf38ox/found_this_kitten_at_a_gas_station_and_trying_to/
...

Sheet 社区汇总
A1: 社区 | B1: 帖子行数 | C1: 有缩略图 | D1: 零评论帖 | E1: 分数隐藏/零 | F1: 评论覆盖帖 ID | G1: 抓取可见评论 | H1: 未展开占位
A2: r/Cats | B2: 300 | C2: 271 | D2: 32 | E2: 1 | F2: t3_1vf38ox | G2: 499 | H2: 73
A3: r/aww | B3: 300 | C3: 299 | D3: 40 | E3: 2 | F3: t3_1vejhaq | G3: 149 | H3: 0
A4: r/OneOrangeBraincell | B4: 300 | C4: 284 | D4: 40 | E4: 2 | F4: t3_1ve5pof | G4: 346 | H4: 0
A5: r/AnimalsBeingDerps | B5: 300 | C5: 296 | D5: 5 | E5: 1 | F5: t3_1uwss5p | G5: 259 | H5: 0
A6: r/blackcats | B6: 300 | C6: 288 | D6: 65 | E6: 1 | F6: t3_1vcqklb | G6: 271 | H6: 0
A7: r/CatDistributionSystem | B7: 300 | C7: 293 | D7: 0 | E7: 1 | F7: t3_1uqpi7u | G7: 482 | H7: 17
A8: r/TuxedoCats | B8: 300 | C8: 300 | D8: 40 | E8: 0 | F8: t3_1vcne63 | G8: 102 | H8: 0
A9: r/AnimalsBeingBros | B9: 300 | C9: 258 | D9: 2 | E9: 0 | F9: t3_1lvqybf | G9: 439 | H9: 67
A10: r/Catswithjobs | B10: 300 | C10: 298 | D10: 0 | E10: 0 | F10: t3_1v2we6u | G10: 252 | H10: 0
A11: r/WhatsWrongWithYourDog | B11: 300 | C11: 276 | D11: 11 | E11: 0 | F11: t3_1uv0ibg | G11: 476 | H11: 32
A12: r/rarepuppers | B12: 300 | C12: 300 | D12: 8 | E12: 1 | F12: t3_1vdxqqq | G12: 134 | H12: 0
